Workbook

Sheet START HERE
A1: 📊 DATASIFT KPI COMMAND CENTER
A2: Your Complete Business Performance Dashboard
A4: 👋 WELCOME! Here's how to use this dashboard:
A6: 1️⃣ | B6: YELLOW CELLS = INPUT | D6: These are the ONLY cells you need to edit. Enter your data here.
A7: 2️⃣ | B7: GREEN CELLS = AUTO-CALC | D7: These update automatically. Never edit these - they contain formulas.
A8: 3️⃣ | B8: CHARTS UPDATE LIVE | D8: All charts refresh instantly when you change any yellow input cell.
A9: 4️⃣ | B9: START WITH GOALS | D9: Go to 'Goals & Setup' tab first to set your targets.
A10: 5️⃣ | B10: ENTER MONTHLY DATA | D10: Then go to 'Monthly Data' tab to enter your actual performance.
A11: 6️⃣ | B11: VIEW YOUR DASHBOARD | D11: Check 'Dashboard' tab to see your performance at a glance.
A14: 🎨 COLOR LEGEND
B16: Yellow | C16: INPUT - Enter your data here
B17: Green | C17: AUTO-CALCULATED - Don't edit
B18: Light Green | C18: ON TARGET - Meeting goals
B19: Orange | C19: WARNING - Below target
B20: Red | C20: NEEDS ATTENTION - Significantly below target
A23: 📑 SHEET GUIDE
A25: → | B25: Goals & Setup | C25: Set your annual goals and business parameters | G25: START HERE FIRST
A26: → | B26: Monthly Data | C26: Enter your monthly performance numbers | G26: UPDATE MONTHLY
A27: → | B27: Dashboard | C27: View your KPIs, charts, and performance summary | G27: CHECK DAILY/WEEKLY
A28: → | B28: Daily Tracker | C28: Track daily prospecting and calling activity | G28: OPTIONAL - FOR Caller NameS
A29: → | B29: Lead Manager Tracker | C29: Track daily lead management activity | G29: OPTIONAL - FOR LEAD MANAGERS

Sheet Goals & Setup
A1: ⚙️ GOALS & SETUP
A3: 📋 Enter your business goals below. These drive all calculations in the dashboard.
A5: 💰 REVENUE GOALS
A7: Setting | B7: Your Value | C7: Description | D7: Example
A8: Annual Revenue Goal | B8: 500000 | C8: Your target revenue for the year | D8: $500K - $2M typical
A9: Average Deal Size | B9: 20000 | C9: Average profit per closed deal | D9: $15K - $50K typical
A10: Close Rate | B10: 0.9 | C10: % of contracts that close | D10: 70-85% typical
A12: 📊 YOUR CONVERSION RATIOS
A14: 📋 These ratios come from your historical data. Update them as you get more data.
A16: Ratio | B16: Your Value | C16: What It Means | D16: Industry Avg
A17: Dials per Lead | B17: 50 | C17: How many dials to get 1 lead | D17: 60-100 | E17: FTM Dials
A18: Leads per Contract | B18: 30 | C18: How many leads to get 1 contract | D18: 40-70 | E18: Bulk Seq
A19: Offers per Contract | B19: 6 | C19: How many offers to get 1 contract | D19: 5-10
A21: 🎯 YOUR CALCULATED REQUIREMENTS
A23: 📋 These are auto-calculated based on your goals above. This is what you need to hit your revenue target.
A25: Metric | B25: Annual | C25: Monthly | D25: Weekly
A26: Deals Required | B26: =B8/B9 -> 25 | C26: =B26/12 -> 2.0833333 | D26: =B26/52 -> 0.48076923
A27: Contracts Required | B27: =B26/B10 -> 27.777778 | C27: =B27/12 -> 2.3148148 | D27: =B27/52 -> 0.53418803
A28: Offers Required | B28: =B27*B19 -> 166.66667 | C28: =B28/12 -> 13.888889 | D28: =B28/52 -> 3.2051282
A29: Leads Required | B29: =B27*B18 -> 833.33333 | C29: =B29/12 -> 69.444444 | D29: =B29/52 -> 16.025641
A30: Dials Required | B30: =B29*B17 -> 41666.667 | C30: =B30/12 -> 3472.2222 | D30: =B30/52 -> 801.28205
A32: 📋 LEAD MANAGER TARGETS
A33: Set daily targets for your Lead Manager. These drive accountability and pipeline health.
A34: Metric | B34: Daily Target | C34: Description | D34: Benchmark
A35: Attempts per Day | B35: 50 | C35: Total leads touched (new + follow-up) | D35: 40-60 typical
A36: New Leads Called | B36: 5 | C36: First-time contacts on inbound leads | D36: 3-8 typical
A37: Follow-ups per Day | B37: 20 | C37: CRM follow-up tasks completed | D37: 15-30 typical
A38: Leads Qualified per Day | B38: 3 | C38: Passed 4 Pillars check | D38: 2-5 typical
A39: Appts Set per Day | B39: 2 | C39: Qualified leads sent to closer | D39: 1-3 typical

Sheet Monthly Data
A1: 📅 MONTHLY PERFORMANCE DATA
A3: 📋 Enter your monthly numbers in the YELLOW cells below. Totals calculate automatically.
A5: METRIC | B5: Jan | C5: Feb | D5: Mar | E5: Apr | F5: May | G5: Jun | H5: Jul | I5: Aug | J5: Sep | K5: Oct | L5: Nov | M5: Dec | N5: TOTAL | O5: TARGET
A6: 📞 LEAD GENERATION | P6: 32 dials = correct number
A7: Dials Made | B7: 4209 | C7: 4534 | D7: 4101 | E7: 3573 | F7: 4198 | G7: 5865 | H7: 8362 | I7: 7522 | J7: 7464 | K7: 5991 | L7: 5068 | M7: 6534 | N7: =SUM(B7:M7) -> 67421 | O7: ='Goals & Setup'!C30*12 -> 41666.667
A8: Correct Numbers | B8: 112 | C8: 141 | D8: 116 | E8: 162 | F8: 138 | G8: 171 | H8: 268 | I8: 200 | J8: 201 | K8: 175 | L8: 157 | M8: 208 | N8: =SUM(B8:M8) -> 2049 | O8: -
A9: Leads Generated | B9: 66 | C9: 62 | D9: 51 | E9: 70 | F9: 51 | G9: 77 | H9: 102 | I9: 92 | J9: 89 | K9: 74 | L9: 61 | M9: 75 | N9: =SUM(B9:M9) -> 870 | O9: ='Goals & Setup'!C29*12 -> 833.33333
A10: 🎯 LEAD MANAGEMENT
A11: Leads Qualified | B11: 33 | C11: 22 | D11: 21 | E11: 31 | F11: 21 | G11: 27 | H11: 31 | I11: 42 | J11: 28 | K11: 29 | L11: 21 | M11: 21 | N11: =SUM(B11:M11) -> 327 | O11: -
A12: Offer Appointments | B12: 18 | C12: 13 | D12: 11 | E12: 13 | F12: 6 | G12: 18 | H12: 9 | I12: 13 | J12: 15 | K12: 6 | L12: 7 | M12: 7 | N12: =SUM(B12:M12) -> 136 | O12: -
A13: 📝 ACQUISITIONS
A14: Offers Made | B14: 15 | C14: 12 | D14: 8 | E14: 12 | F14: 4 | G14: 14 | H14: 5 | I14: 11 | J14: 11 | K14: 5 | L14: 5 | M14: 6 | N14: =SUM(B14:M14) -> 108 | O14: -
A15: Contracts Signed | B15: 3 | C15: 2 | E15: 1 | G15: 5 | H15: 2 | I15: 1 | K15: 1 | M15: 1 | N15: =SUM(B15:M15) -> 16 | O15: ='Goals & Setup'!C27*12 -> 27.777778
A16: Booked Revenue | B16: 110000 | C16: 145500 | G16: 137125 | H16: 30000 | K16: 28000 | M16: 44000 | N16: =SUM(B16:M16) -> 494625 | O16: ='Goals & Setup'!B8 -> 500000
A17: 💰 DISPOSITION
A18: Closed Deals | B18: 1 | C18: 1 | D18: 2 | E18: 1 | H18: 1 | I18: 2 | J18: 1 | K18: 1 | L18: 1 | M18: 1 | N18: =SUM(B18:M18) -> 12 | O18: ='Goals & Setup'!C26*12 -> 25
A19: Closed Revenue | B19: 10000 | C19: 24000 | D19: 86000 | E19: 35500 | H19: 125000 | I19: 111125 | J19: 15000 | K19: -19000 | L19: 28000 | N19: =SUM(B19:M19) -> 415625 | O19: ='Goals & Setup'!B8 -> 500000
A20: 💸 MARKETING COSTS
A21: SMS/Text Spend | B21: 259 | C21: 194 | D21: 176 | E21: 138 | F21: 151 | G21: 195 | H21: 302 | I21: 217 | J21: 183 | K21: 201 | L21: 212 | M21: 210 | N21: =SUM(B21:M21) -> 2438 | O21: -
A22: Calling Spend | B22: 815 | C22: 610 | D22: 552 | E22: 435 | F22: 474 | G22: 614 | H22: 949 | I22: 682 | J22: 576 | K22: 633 | L22: 666 | M22: 660 | N22: =SUM(B22:M22) -> 7666
A23: Direct Mail Spend | B23: 1667 | C23: 1248 | D23: 1129 | E23: 890 | F23: 970 | G23: 1256 | H23: 1940 | I23: 1394 | J23: 1178 | K23: 1295 | L23: 1363 | M23: 1350 | N23: =SUM(B23:M23) -> 15680
A24: Deep Prospecting Spend | B24: 741 | C24: 555 | D24: 502 | E24: 396 | F24: 431 | G24: 558 | H24: 862 | I24: 620 | J24: 524 | K24: 575 | L24: 606 | M24: 600 | N24: =SUM(B24:M24) -> 6970
A25: Door Knocking Spend | B25: 222 | C25: 166 | D25: 150 | E25: 119 | F25: 129 | G25: 167 | H25: 259 | I25: 186 | J25: 157 | K25: 173 | L25: 182 | M25: 180 | N25: =SUM(B25:M25) -> 2090
A26: Total Marketing Spend | B26: =SUM(B21:B25) -> 3704 | C26: =SUM(C21:C25) -> 2773 | D26: =SUM(D21:D25) -> 2509 | E26: =SUM(E21:E25) -> 1978 | F26: =SUM(F21:F25) -> 2155 | G26: =SUM(G21:G25) -> 2790 | H26: =SUM(H21:H25) -> 4312 | I26: =SUM(I21:I25) -> 3099 | ... M26: =SUM(M21:M25) -> 3000 | N26: =SUM(B26:M26) -> 34844

Sheet Dashboard
A1: 📊 PERFORMANCE DASHBOARD
A3: 🏆 SCORECARD - Year to Date
A4: Metric | B4: Actual | C4: Target | D4: % of Target | E4: Status | F4: Gap
A5: Closed Revenue | B5: ='Monthly Data'!N19 -> 415625 | C5: ='Goals & Setup'!B8 -> 500000 | D5: =IFERROR(B5/C5,0) -> 0.83125 | E5: =IF(D5>=0.9,"✅ On Track",IF(D5>=0.7,"⚠️ Behind","❌ At Risk")) -> ⚠️ Behind | F5: =C5-B5 -> 84375
A6: Closed Deals | B6: ='Monthly Data'!N18 -> 12 | C6: ='Goals & Setup'!B26 -> 25 | D6: =IFERROR(B6/C6,0) -> 0.48 | E6: =IF(D6>=0.9,"✅ On Track",IF(D6>=0.7,"⚠️ Behind","❌ At Risk")) -> ❌ At Risk | F6: =C6-B6 -> 13
A7: Contracts Signed | B7: ='Monthly Data'!N15 -> 16 | C7: ='Goals & Setup'!B27 -> 27.777778 | D7: =IFERROR(B7/C7,0) -> 0.576 | E7: =IF(D7>=0.9,"✅ On Track",IF(D7>=0.7,"⚠️ Behind","❌ At Risk")) -> ❌ At Risk | F7: =C7-B7 -> 11.777778
A8: Leads Generated | B8: ='Monthly Data'!N9 -> 870 | C8: ='Goals & Setup'!B29 -> 833.33333 | D8: =IFERROR(B8/C8,0) -> 1.044 | E8: =IF(D8>=0.9,"✅ On Track",IF(D8>=0.7,"⚠️ Behind","❌ At Risk")) -> ✅ On Track | F8: =C8-B8 -> -36.666667
A9: Total Dials | B9: ='Monthly Data'!N7 -> 67421 | C9: ='Goals & Setup'!B30 -> 41666.667 | D9: =IFERROR(B9/C9,0) -> 1.618104 | E9: =IF(D9>=0.9,"✅ On Track",IF(D9>=0.7,"⚠️ Behind","❌ At Risk")) -> ✅ On Track | F9: =C9-B9 -> -25754.333
A11: 📈 KEY EFFICIENCY RATIOS
A12: Ratio | B12: Your Value | C12: Target | D12: Status
A13: Dials per Lead | B13: =IFERROR('Monthly Data'!N7/'Monthly Data'!N9,0) -> 77.495402 | C13: ='Goals & Setup'!B17 -> 50 | D13: =IF(B13<=C13,"✅ Good","⚠️ High") -> ⚠️ High
A14: Leads per Contract | B14: =IFERROR('Monthly Data'!N9/'Monthly Data'!N15,0) -> 54.375 | C14: ='Goals & Setup'!B18 -> 30 | D14: =IF(B14<=C14,"✅ Good","⚠️ High") -> ⚠️ High
A15: Offers per Contract | B15: =IFERROR('Monthly Data'!N14/'Monthly Data'!N15,0) -> 6.75 | C15: ='Goals & Setup'!B19 -> 6 | D15: =IF(B15<=C15,"✅ Good","⚠️ High") -> ⚠️ High
A16: Close Rate | B16: =IFERROR('Monthly Data'!N18/'Monthly Data'!N15,0) -> 0.75 | C16: ='Goals & Setup'!B10 -> 0.9 | D16: =IF(B16>=C16,"✅ Good","⚠️ Low") -> ⚠️ Low
A17: Cost per Lead | B17: =IFERROR('Monthly Data'!N26/'Monthly Data'!N9,0) -> 40.050575 | C17: 50 | D17: =IF(B17<=C17,"✅ Good","⚠️ High") -> ✅ Good
A18: ROI | B18: =IFERROR('Monthly Data'!N19/'Monthly Data'!N26,0) -> 11.928166 | C18: 10 | D18: =IF(B18>=C18,"✅ Good","⚠️ Low") -> ⚠️ Low
A20: 💵 FINANCIAL SUMMARY
A21: Metric | B21: Amount | C21: Notes
A22: Total Closed Revenue | B22: ='Monthly Data'!N19 -> 415625 | C22: Actual revenue collected
A23: Total Booked Revenue | B23: ='Monthly Data'!N16 -> 494625 | C23: Revenue under contract
A24: Total Marketing Spend | B24: ='Monthly Data'!N26 -> 34844 | C24: All marketing costs
A25: Net Profit (from Marketing) | B25: ='Monthly Data'!N19-'Monthly Data'!N26 -> 380781 | C25: Revenue minus marketing
A26: Overall ROI | B26: =IFERROR('Monthly Data'!N19/'Monthly Data'!N26,0) -> 11.928166 | C26: Return on marketing spend
A28: 💰 TRUE PROFIT & LOSS
A29: Metric | B29: Amount | C29: Notes
A30: Total Closed Revenue | B30: ='Monthly Data'!N19 -> 415625 | C30: All closed deals
A31: Total Team Costs | B31: =Expenses!C13 -> 69600 | C31: Annual team payroll
A32: Total Software Costs | B32: =Expenses!C25 -> 13410 | C32: Annual software/tools
A33: Total Marketing Spend | B33: ='Monthly Data'!N26 -> 34844 | C33: All marketing channels
A34: Total All Expenses | B34: =Expenses!C39 -> 92610 | C34: Team + software + marketing
A35: True Net Profit | B35: ='Monthly Data'!N19-Expenses!C39 -> 323015 | C35: Revenue minus ALL costs
A36: Net Margin % | B36: =IFERROR(B35/B30,0) -> 0.77717895 | C36: Target: 30-50%

Sheet Daily Prospector CC Tracker
A1: 📅 2026 DAILY ACTIVITY TRACKER- Caller 1
A3: 📋 Track daily prospecting activity organized by week. Enter data in YELLOW cells. Weekly totals calculate automatically.
A5: 📆 WEEK 1 | Dec 29 - Jan 04, 2026
A6: Day | B6: Date | C6: Caller Name | D6: Hours | E6: Dials | F6: Correct # | G6: Leads | H6: Appts | I6: Contracts
A7: Mon | B7: 46385 | C7: Ty | D7: 2 | E7: 140 | F7: 3 | G7: 1
A8: Tue | B8: 46386 | C8: Ty | D8: 2 | E8: 140 | F8: 4 | G8: 10
A9: Wed | B9: 46387 | C9: Ty | D9: 3 | E9: 140 | F9: 2 | G9: 1
A10: Thu | B10: 46023 | C10: Ty | D10: 3 | E10: 140 | F10: 3 | G10: 1
A11: Fri | B11: 46024 | C11: Ty | D11: 2 | E11: 140 | F11: 5 | G11: 2
A12: Sat | B12: 01/03
A13: Sun | B13: 01/04
A14: WEEK TOTAL | D14: =SUM(D7:D13) -> 12 | E14: =SUM(E7:E13) -> 700 | F14: =SUM(F7:F13) -> 17 | G14: =SUM(G7:G13) -> 15 | H14: =SUM(H7:H13) -> 0 | I14: =SUM(I7:I13) -> 0
A16: 📆 WEEK 2 | Jan 05 - Jan 11, 2026
A17: Day | B17: Date | C17: Caller Name | D17: Hours | E17: Dials | F17: Correct # | G17: Leads | H17: Appts | I17: Contracts
A18: Mon | B18: 01/05 | C18: Ty | D18: 3 | E18: 180 | F18: 5 | G18: 3 | H18: 1 | I18: 0
A19: Tue | B19: 01/06 | C19: Ty | D19: 2.5 | E19: 160 | F19: 4 | G19: 2 | H19: 0 | I19: 0
A20: Wed | B20: 01/07 | C20: Ty | D20: 3 | E20: 175 | F20: 6 | G20: 4 | H20: 1 | I20: 0
A21: Thu | B21: 01/08 | C21: Ty | D21: 2 | E21: 150 | F21: 3 | G21: 2 | H21: 0 | I21: 0
A22: Fri | B22: 01/09 | C22: Ty | D22: 3 | E22: 185 | F22: 5 | G22: 3 | H22: 1 | I22: 0
A23: Sat | B23: 01/10
A24: Sun | B24: 01/11
A25: WEEK TOTAL | D25: =SUM(D18:D24) -> 13.5 | E25: =SUM(E18:E24) -> 850 | F25: =SUM(F18:F24) -> 23 | G25: =SUM(G18:G24) -> 14 | H25: =SUM(H18:H24) -> 3 | I25: =SUM(I18:I24) -> 0
A27: 📆 WEEK 3 | Jan 12 - Jan 18, 2026
A28: Day | B28: Date | C28: Caller Name | D28: Hours | E28: Dials | F28: Correct # | G28: Leads | H28: Appts | I28: Contracts
A29: Mon | B29: 01/12 | C29: Ty | D29: 3 | E29: 200 | F29: 6 | G29: 4 | H29: 1 | I29: 1
A30: Tue | B30: 01/13 | C30: Ty | D30: 3 | E30: 190 | F30: 5 | G30: 3 | H30: 1 | I30: 0
A31: Wed | B31: 01/14 | C31: Ty | D31: 2.5 | E31: 170 | F31: 4 | G31: 2 | H31: 0 | I31: 0
A32: Thu | B32: 01/15 | C32: Ty | D32: 3 | E32: 210 | F32: 7 | G32: 4 | H32: 2 | I32: 0
A33: Fri | B33: 01/16 | C33: Ty | D33: 2.5 | E33: 180 | F33: 5 | G33: 3 | H33: 1 | I33: 0
A34: Sat | B34: 01/17
A35: Sun | B35: 01/18
A36: WEEK TOTAL | D36: =SUM(D29:D35) -> 14 | E36: =SUM(E29:E35) -> 950 | F36: =SUM(F29:F35) -> 27 | G36: =SUM(G29:G35) -> 16 | H36: =SUM(H29:H35) -> 5 | I36: =SUM(I29:I35) -> 1
A38: 📆 WEEK 4 | Jan 19 - Jan 25, 2026
A39: Day | B39: Date | C39: Caller Name | D39: Hours | E39: Dials | F39: Correct # | G39: Leads | H39: Appts | I39: Contracts
A40: Mon | B40: 01/19 | C40: Ty | D40: 2.5 | E40: 185 | F40: 5 | G40: 3 | H40: 1 | I40: 0
A41: Tue | B41: 01/20 | C41: Ty | D41: 3 | E41: 210 | F41: 6 | G41: 4 | H41: 1 | I41: 0
A42: Wed | B42: 01/21 | C42: Ty | D42: 3 | E42: 195 | F42: 5 | G42: 3 | H42: 0 | I42: 1
A43: Thu | B43: 01/22 | C43: Ty | D43: 2.5 | E43: 175 | F43: 4 | G43: 2 | H43: 1 | I43: 0
A44: Fri | B44: 01/23 | C44: Ty | D44: 3 | E44: 194 | F44: 6 | G44: 3 | H44: 1 | I44: 1
A45: Sat | B45: 01/24
...

Sheet Lead Manager Tracker
A1: 📋 2026 DAILY ACTIVITY TRACKER - Lead Manager
A3: Track daily lead management activity. Enter data in YELLOW cells. Weekly totals calculate automatically.
A5: 📆 WEEK 1 | Dec 29 - Jan 04, 2026
A6: Day | B6: Date | C6: LM Name | D6: Hours | E6: Total Attempts | F6: New Leads Called | G6: Follow-ups Done | H6: Leads Qualified | I6: Appts Set | J6: Push-backs Rcvd
A7: Mon | B7: 12/29 | C7: Jordan | D7: 5 | E7: 42 | F7: 4 | G7: 18 | H7: 2 | I7: 1 | J7: 0
A8: Tue | B8: 12/30 | C8: Jordan | D8: 5 | E8: 48 | F8: 5 | G8: 22 | H8: 2 | I8: 1 | J8: 1
A9: Wed | B9: 12/31 | C9: Jordan | D9: 4 | E9: 38 | F9: 3 | G9: 15 | H9: 1 | I9: 0 | J9: 0
A10: Thu | B10: 01/01 | C10: Jordan | D10: 5 | E10: 45 | F10: 4 | G10: 20 | H10: 2 | I10: 1 | J10: 0
A11: Fri | B11: 01/02 | C11: Jordan | D11: 5 | E11: 50 | F11: 5 | G11: 24 | H11: 3 | I11: 2 | J11: 1
A12: Sat | B12: 01/03
A13: Sun | B13: 01/04
A14: WEEK TOTAL | D14: =SUM(D7:D13) -> 24 | E14: =SUM(E7:E13) -> 223 | F14: =SUM(F7:F13) -> 21 | G14: =SUM(G7:G13) -> 99 | H14: =SUM(H7:H13) -> 10 | I14: =SUM(I7:I13) -> 5 | J14: =SUM(J7:J13) -> 2
A16: 📆 WEEK 2 | Jan 05 - Jan 11, 2026
A17: Day | B17: Date | C17: LM Name | D17: Hours | E17: Total Attempts | F17: New Leads Called | G17: Follow-ups Done | H17: Leads Qualified | I17: Appts Set | J17: Push-backs Rcvd
A18: Mon | B18: 01/05 | C18: Jordan | D18: 6 | E18: 52 | F18: 5 | G18: 24 | H18: 2 | I18: 1 | J18: 1
A19: Tue | B19: 01/06 | C19: Jordan | D19: 5 | E19: 48 | F19: 4 | G19: 20 | H19: 1 | I19: 0 | J19: 0
A20: Wed | B20: 01/07 | C20: Jordan | D20: 6 | E20: 55 | F20: 5 | G20: 26 | H20: 3 | I20: 2 | J20: 0
A21: Thu | B21: 01/08 | C21: Jordan | D21: 5 | E21: 47 | F21: 3 | G21: 22 | H21: 1 | I21: 1 | J21: 1
A22: Fri | B22: 01/09 | C22: Jordan | D22: 6 | E22: 53 | F22: 4 | G22: 25 | H22: 2 | I22: 1 | J22: 0
A23: Sat | B23: 01/10
A24: Sun | B24: 01/11
A25: WEEK TOTAL | D25: =SUM(D18:D24) -> 28 | E25: =SUM(E18:E24) -> 255 | F25: =SUM(F18:F24) -> 21 | G25: =SUM(G18:G24) -> 117 | H25: =SUM(H18:H24) -> 9 | I25: =SUM(I18:I24) -> 5 | J25: =SUM(J18:J24) -> 2
A27: 📆 WEEK 3 | Jan 12 - Jan 18, 2026
A28: Day | B28: Date | C28: LM Name | D28: Hours | E28: Total Attempts | F28: New Leads Called | G28: Follow-ups Done | H28: Leads Qualified | I28: Appts Set | J28: Push-backs Rcvd
A29: Mon | B29: 01/12 | C29: Jordan | D29: 5 | E29: 48 | F29: 4 | G29: 22 | H29: 1 | I29: 1 | J29: 0
A30: Tue | B30: 01/13 | C30: Jordan | D30: 6 | E30: 53 | F30: 5 | G30: 25 | H30: 2 | I30: 1 | J30: 0
A31: Wed | B31: 01/14 | C31: Jordan | D31: 5 | E31: 45 | F31: 3 | G31: 20 | H31: 2 | I31: 1 | J31: 1
A32: Thu | B32: 01/15 | C32: Jordan | D32: 6 | E32: 51 | F32: 4 | G32: 24 | H32: 1 | I32: 0 | J32: 0
A33: Fri | B33: 01/16 | C33: Jordan | D33: 5 | E33: 49 | F33: 4 | G33: 22 | H33: 2 | I33: 1 | J33: 0
A34: Sat | B34: 01/17
A35: Sun | B35: 01/18
A36: WEEK TOTAL | D36: =SUM(D29:D35) -> 27 | E36: =SUM(E29:E35) -> 246 | F36: =SUM(F29:F35) -> 20 | G36: =SUM(G29:G35) -> 113 | H36: =SUM(H29:H35) -> 8 | I36: =SUM(I29:I35) -> 4 | J36: =SUM(J29:J35) -> 1
A38: 📆 WEEK 4 | Jan 19 - Jan 25, 2026
A39: Day | B39: Date | C39: LM Name | D39: Hours | E39: Total Attempts | F39: New Leads Called | G39: Follow-ups Done | H39: Leads Qualified | I39: Appts Set | J39: Push-backs Rcvd
A40: Mon | B40: 01/19 | C40: Jordan | D40: 6 | E40: 55 | F40: 5 | G40: 25 | H40: 2 | I40: 1 | J40: 1
A41: Tue | B41: 01/20 | C41: Jordan | D41: 5 | E41: 50 | F41: 4 | G41: 22 | H41: 2 | I41: 1 | J41: 0
A42: Wed | B42: 01/21 | C42: Jordan | D42: 6 | E42: 52 | F42: 4 | G42: 24 | H42: 1 | I42: 1 | J42: 0
A43: Thu | B43: 01/22 | C43: Jordan | D43: 6 | E43: 54 | F43: 5 | G43: 26 | H43: 3 | I43: 2 | J43: 1
A44: Fri | B44: 01/23 | C44: Jordan | D44: 5 | E44: 48 | F44: 3 | G44: 20 | H44: 1 | I44: 1 | J44: 0
A45: Sat | B45: 01/24
...

Sheet Transactions
A1: 💼 TRANSACTION TRACKER
A3: 📋 Track every deal from contract to close. Enter data in YELLOW cells. Pipeline summary auto-calculates.
A5: Property Address | B5: Lead Source | C5: Contract Date | D5: Contract Price | E5: ARV | F5: Repair Est. | G5: Assignment Fee | H5: Buyer | I5: Close Date | J5: Closed Revenue | K5: Status | L5: Notes
A6: 123 Main St | B6: FTM Niche | C6: 2026-01-15 | D6: 85000 | E6: 150000 | F6: 25000 | G6: 15000 | H6: ABC Investments | I6: 2026-02-28 | J6: Closed | K6: Closed | L6: First deal of year
A7: 456 Oak Ave | B7: Direct Mail | C7: 2026-01-22 | D7: 120000 | E7: 200000 | F7: 35000 | G7: 22000 | H7: XYZ Holdings | I7: 2026-03-15 | J7: Closed | K7: Closed | L7: Probate lead
A8: 789 Pine Rd | B8: FTM Niche | C8: 2026-02-10 | D8: 95000 | E8: 175000 | F8: 40000 | G8: 18000 | H8: Flip Masters LLC | I8: 2026-03-25 | J8: Under Contract | K8: Under Contract | L8: Closing next week
A9: 321 Elm St | B9: Bulk Sequential | C9: 2026-02-18 | D9: 110000 | E9: 185000 | F9: 30000 | G9: 20000 | H9: Quick Cash Buyers | J9: Under Contract | K9: In Negotiation | L9: Waiting on title
A10: 1024 Cedar Ln | B10: FTM Niche | C10: 2026-03-05 | D10: 78000 | E10: 140000 | F10: 22000 | G10: 12000 | H10: Summit Capital | I10: 2026-04-10 | J10: Closed | K10: Closed | L10: Probate deal
A11: 555 Maple Dr | B11: Bulk Sequential | C11: 2026-03-18 | D11: 92000 | E11: 160000 | F11: 28000 | G11: 16000 | H11: TN Flippers LLC | I11: 2026-04-22 | J11: Closed | K11: Closed | L11: Stacked list
A12: 812 Walnut St | B12: Deep Prospecting | C12: 2026-05-02 | D12: 65000 | E12: 130000 | F12: 35000 | G12: 10000 | H12: ABC Investments | I12: 2026-06-15 | J12: Closed | K12: Closed | L12: Heir property
A13: 2200 Birch Ave | B13: FTM Niche | C13: 2026-06-10 | D13: 105000 | E13: 190000 | F13: 40000 | G13: 18000 | H13: Quick Cash Buyers | I13: 2026-07-20 | J13: Closed | K13: Closed | L13: Tax delinquent
A14: 740 Spruce Ct | B14: Bulk Sequential | C14: 2026-06-22 | D14: 88000 | E14: 155000 | F14: 25000 | G14: 14000 | H14: Flip Masters LLC | I14: 2026-08-01 | J14: Closed | K14: Closed | L14: High equity absentee
A15: 1515 Dogwood Pkwy | B15: Direct Mail | C15: 2026-07-08 | D15: 72000 | E15: 135000 | F15: 30000 | G15: 11000 | H15: Pinnacle Buyers | I15: 2026-08-15 | J15: Closed | K15: Closed | L15: Probate mailer response
A16: 309 Hickory Rd | B16: FTM Niche | C16: 2026-08-14 | D16: 95000 | E16: 170000 | F16: 32000 | G16: 15000 | H16: XYZ Holdings | I16: 2026-09-20 | J16: Closed | K16: Closed | L16: Eviction list
A17: 4420 Ash Blvd | B17: Deep Prospecting | C17: 2026-08-28 | D17: 110000 | E17: 195000 | F17: 38000 | G17: 20000 | H17: Summit Capital | I17: 2026-10-05 | J17: Closed | K17: Closed | L17: Inherited property
A18: 667 Poplar Way | B18: Referral | C18: 2026-09-12 | D18: 82000 | E18: 145000 | F18: 20000 | G18: 13000 | H18: TN Flippers LLC | I18: 2026-10-15 | J18: Closed | K18: Closed | L18: Agent referral
A19: 1888 Sycamore Ave | B19: Bulk Sequential | C19: 2026-09-25 | D19: 98000 | E19: 175000 | F19: 35000 | G19: 17000 | H19: Quick Cash Buyers | I19: 2026-10-30 | J19: Closed | K19: Closed | L19: Tired landlord
A20: 225 Magnolia St | B20: FTM Niche | C20: 2026-10-10 | D20: 68000 | E20: 125000 | F20: 18000 | G20: 12000 | H20: ABC Investments | J20: Closed | K20: Closed | L20: Code violation
A21: 3100 Chestnut Dr | B21: FTM Niche | C21: 2026-12-05 | D21: 115000 | E21: 200000 | F21: 40000 | G21: 19000 | H21: Flip Masters LLC | I21: 2026-12-28 | J21: Closed | K21: Closed | L21: Probate deal
A31: 📊 PIPELINE SUMMARY (Auto-calculated)
A32: Status | B32: Count | C32: Total Value | D32: Avg Deal Size
A33: Closed | B33: 14 | C33: =SUMIF(K6:K29,A33,J6:J29) -> 0 | D33: =IFERROR(C33/B33,0) -> 0
A34: Under Contract | B34: 1 | C34: =SUMIF(K6:K29,A34,G6:G29) -> 18000 | D34: =IFERROR(C34/B34,0) -> 18000
A35: In Negotiation | B35: 1 | C35: =SUMIF(K6:K29,A35,G6:G29) -> 20000 | D35: =IFERROR(C35/B35,0) -> 20000
A36: Dead | B36: =COUNTIF(K6:K29,A36) -> 0 | C36: =SUMIF(K6:K29,A36,G6:G29) -> 0 | D36: =IFERROR(C36/B36,0) -> 0
A37: TOTAL PIPELINE | B37: 16 | C37: =SUM(C33:C36) -> 38000 | D37: =IFERROR(C37/B37,0) -> 2375
A39: 📈 DEALS BY LEAD SOURCE
A40: Lead Source | B40: Deals | C40: Revenue | D40: Avg Revenue
A41: FTM Niche | B41: 7 | C41: =SUMIF(B6:B29,A41,J6:J29) -> 0 | D41: =IFERROR(C41/B41,0) -> 0
A42: Bulk Sequential | B42: 3 | C42: =SUMIF(B6:B29,A42,J6:J29) -> 0 | D42: =IFERROR(C42/B42,0) -> 0
A43: Direct Mail | B43: 2 | C43: =SUMIF(B6:B29,A43,J6:J29) -> 0 | D43: =IFERROR(C43/B43,0) -> 0
A44: Deep Prospecting | B44: 2 | C44: =SUMIF(B6:B29,A44,J6:J29) -> 0 | D44: =IFERROR(C44/B44,0) -> 0
A45: Referral | B45: 1 | C45: =SUMIF(B6:B29,A45,J6:J29) -> 0 | D45: =IFERROR(C45/B45,0) -> 0
A46: AI/Predictive | B46: 0 | C46: =SUMIF(B6:B29,A46,J6:J29) -> 0 | D46: =IFERROR(C46/B46,0) -> 0
A47: PPC/Website | B47: 1
A48: Other | B48: 0

Sheet Expenses
A1: 💸 EXPENSE TRACKER
A3: 📋 Track all business expenses. Enter monthly costs in YELLOW cells. Totals auto-calculate.
A5: 👥 TEAM EXPENSES
A6: Role/Item | B6: Monthly Cost | C6: Annual Cost | D6: Notes
A7: Cold Caller Name | B7: 800 | C7: =B7*12 -> 9600 | D7: Overseas VA
A8: Data Manager | B8: 800 | C8: =B8*12 -> 9600 | D8: Part-time
A9: Lead Manager | B9: 1200 | C9: =B9*12 -> 14400 | D9: Overseas VA, full-time
A10: Acquisitions Manager | B10: 3000 | C10: =B10*12 -> 36000 | D10: Commission-based
A11: Dispo Manager | B11: 0 | C11: =B11*12 -> 0 | D11: If applicable
A13: Team Subtotal | B13: =SUM(B7:B11) -> 5800 | C13: =SUM(C7:C11) -> 69600
A15: 💻 SOFTWARE & TOOLS
A16: Role/Item | B16: Monthly Cost | C16: Annual Cost | D16: Notes
A17: DataSift | B17: 497 | C17: =B17*12 -> 5964 | D17: CRM + Data
A18: Dialer (Smrt Phone) | B18: 75 | C18: =B18*12 -> 900
A19: Skip Tracing (BeenVerified) | B19: 39 | C19: =B19*12 -> 468
A20: Slack | B20: 52.5 | C20: =B20*12 -> 630 | D20: Team communication
A21: Website Hosting | B21: 99 | C21: =B21*12 -> 1188
A22: Email Service | B22: 55 | C22: =B22*12 -> 660
A23: Manus AI | B23: 200 | C23: =B23*12 -> 2400
A24: Other Software | B24: 100 | C24: =B24*12 -> 1200
A25: Software Subtotal | B25: =SUM(B17:B24) -> 1117.5 | C25: =SUM(C17:C24) -> 13410
A27: 📣 MARKETING EXPENSES
A28: Role/Item | B28: Monthly Cost | C28: Annual Cost | D28: Notes
A29: Direct Mail | B29: 100 | C29: =B29*12 -> 1200 | D29: First-to-market postcards
A30: SMS/Text Blasts | B30: 500 | C30: =B30*12 -> 6000 | D30: Smarter Contact
A31: Data/List Costs | B31: 200 | C31: =B31*12 -> 2400 | D31: Skip tracing, lists
A32: PPC/Google Ads | B32: 0 | C32: =B32*12 -> 0 | D32: If applicable
A33: Facebook Ads | B33: 0 | C33: =B33*12 -> 0 | D33: If applicable
A34: Other Marketing | B34: 0 | C34: =B34*12 -> 0
A35: Other Marketing | B35: 0 | C35: =B35*12 -> 0
A36: Marketing Subtotal | B36: =SUM(B29:B34) -> 800 | C36: =SUM(C29:C34) -> 9600
A38: 💰 TOTAL EXPENSES
A39: GRAND TOTAL | B39: =B13+B25+B36 -> 7717.5 | C39: =C13+C25+C36 -> 92610

Sheet Direct Mail
A1: 📬 SEQUENTIAL MARKETING TRACKER
A3: 📋 Track both First-to-Market (FTM) Niche Sequential and Bulk Sequential marketing. Purple = FTM, Orange = Bulk. Yellow = Input.
A5: ⚙️ GLOBAL SETTINGS
A6: Setting | B6: Value | C6: Description
A7: Cost per Postcard | B7: 0.55 | C7: REI Sift mail cost
A8: Cost per SMS | B8: 0.01 | C8: Smarter Contact avg
A9: Cost per Cold Call Touch | B9: 0.05 | C9: VA cost per dial
A10: Target Response Rate (Mail) | B10: 0.005 | C10: Industry avg: 0.5%
A11: Response to Lead Rate | B11: 0.6 | C11: % responses → leads
A12: Leads per Contract | B12: 12 | C12: Leads to get 1 contract
A13: Avg Deal Profit | B13: 15000 | C13: Your avg profit/deal
A15: 🎯 FIRST-TO-MARKET (FTM) NICHE SEQUENTIAL
A16: Small volume, high-touch marketing to distress lists (Probate, Eviction, Foreclosure, Tax Delinquent, Code Violation). Send mail immediately when records are pulled, then rehash monthly.
A18: 📊 FTM RECORDS PROJECTOR (Enter your avg monthly records per niche)
A19: Niche List | B19: Avg Monthly | C19: Mail Cost/Mo | D19: Annual Records | E19: Annual Mail Cost | F19: 12-Mo Rehash Total | G19: Rehash Annual Cost
A20: Probate | B20: 150 | C20: =B20*B7 -> 82.5 | D20: =B20*12 -> 1800 | E20: =C20*12 -> 990 | F20: =B20*78 -> 11700 | G20: =F20*B7 -> 6435
A21: Eviction | B21: 0 | C21: =B21*B7 -> 0 | D21: =B21*12 -> 0 | E21: =C21*12 -> 0 | F21: =B21*78 -> 0 | G21: =F21*B7 -> 0
A22: Foreclosure | B22: 0 | C22: =B22*B7 -> 0 | D22: =B22*12 -> 0 | E22: =C22*12 -> 0 | F22: =B22*78 -> 0 | G22: =F22*B7 -> 0
A23: Tax Delinquent | B23: 0 | C23: =B23*B7 -> 0 | D23: =B23*12 -> 0 | E23: =C23*12 -> 0 | F23: =B23*78 -> 0 | G23: =F23*B7 -> 0
A24: Code Violation | B24: 0 | C24: =B24*B7 -> 0 | D24: =B24*12 -> 0 | E24: =C24*12 -> 0 | F24: =B24*78 -> 0 | G24: =F24*B7 -> 0
A25: FTM TOTAL | B25: =SUM(B20:B24) -> 150 | C25: =SUM(C20:C24) -> 82.5 | D25: =SUM(D20:D24) -> 1800 | E25: =SUM(E20:E24) -> 990 | F25: =SUM(F20:F24) -> 11700 | G25: =SUM(G20:G24) -> 6435
A27: 📮 FTM MAIL CAMPAIGN TRACKER
A28: Date | B28: Niche | C28: # Mailed | D28: Cost | E28: Responses | F28: Leads | G28: Appts | H28: Contracts | I28: Revenue | J28: ROI | K28: Notes
A29: 2026-01-15 | B29: Probate | C29: 50 | D29: =C29*B7 -> 27.5 | E29: 3 | F29: 2 | G29: 1 | H29: 0 | I29: 0
A30: 2026-01-22 | B30: Eviction | C30: 45 | D30: =C30*B7 -> 24.75 | E30: 2 | F30: 1 | G30: 0 | H30: 0 | I30: 0
A31: 2026-02-01 | B31: Probate | C31: 52 | D31: =C31*B7 -> 28.6 | E31: 4 | F31: 3 | G31: 2 | H31: 1 | I31: 15000
A32: 2026-02-15 | B32: Probate | C32: 55 | D32: 30.25 | E32: 3 | F32: 2 | G32: 1 | H32: 0 | I32: 0 | J32: =IFERROR(I32/D32,0) -> 0
A33: 2026-03-01 | B33: Probate | C33: 48 | D33: 26.4 | E33: 2 | F33: 1 | G33: 1 | H33: 0 | I33: 0 | J33: =IFERROR(I33/D33,0) -> 0
A34: 2026-03-15 | B34: Tax Delinquent | C34: 62 | D34: 34.1 | E34: 4 | F34: 3 | G34: 2 | H34: 1 | I34: 12000 | J34: =IFERROR(I34/D34,0) -> 351.90616
A35: 2026-04-01 | B35: Probate | C35: 50 | D35: 27.5 | E35: 3 | F35: 2 | G35: 1 | H35: 0 | I35: 0 | J35: =IFERROR(I35/D35,0) -> 0
A36: 2026-04-15 | B36: Eviction | C36: 40 | D36: 22 | E36: 2 | F36: 1 | G36: 0 | H36: 0 | I36: 0 | J36: =IFERROR(I36/D36,0) -> 0
D37: =IF(C37="","",C37*B7) | J37: =IFERROR(I37/D37,0) -> 0
D38: =IF(C38="","",C38*B7) | J38: =IFERROR(I38/D38,0) -> 0
D39: =IF(C39="","",C39*B7) | J39: =IFERROR(I39/D39,0) -> 0
D40: =IF(C40="","",C40*B7) | J40: =IFERROR(I40/D40,0) -> 0
D41: =IF(C41="","",C41*B7) | J41: =IFERROR(I41/D41,0) -> 0
A43: 📦 BULK SEQUENTIAL MARKETING
A44: High volume, multi-channel marketing to stacked lists (High Equity + Absentee + Out-of-State). Use SMS → Cold Call → Mail → Deep Prospect sequence.
A46: 📊 BULK LIST PROJECTOR (Enter your stacked list sizes)
A47: List/Stack | B47: Total Records | C47: SMS Cost | D47: Call Cost | E47: Mail Cost | F47: Total Cost | G47: Est. Leads | H47: Cost/Lead
...

Sheet Review Dashboard
A1: 📊 WEEKLY / MONTHLY REVIEW DASHBOARD
A3: 📋 Use this dashboard for weekly team meetings and monthly reviews. Enter weekly totals by role. Color coding: Blue = Data Manager, Green = Lead Manager, Gold = Acquisitions.
A5: 📅 REVIEW PERIOD | H5: 🔄 MONTHLY FUNNEL SUMMARY
A6: Week Of: | B6: 2026-01-05 | D6: Month: | E6: January | H6: Stage | I6: Count | J6: Conv. Rate | K6: Target | L6: Status
H7: Total Dials | I7: 4209 | J7: 100% | K7: 5625 | L7: =IF(I7>=K7,"✅",IF(I7>=K7*0.8,"⚠️","❌")) -> ❌
A8: 📁 DATA MANAGER KPIs | H8: Correct Numbers | I8: 112 | J8: =IFERROR(I8/I7,0) -> 0.026609646 | K8: 200 | L8: =IF(I8>=K8,"✅",IF(I8>=K8*0.8,"⚠️","❌")) -> ❌
A9: Metric | B9: Week 1 | C9: Week 2 | D9: Week 3 | E9: Week 4 | F9: MTD Total | H9: Total Leads | I9: 66 | J9: =IFERROR(I9/I8,0) -> 0.58928571 | K9: 112 | L9: =IF(I9>=K9,"✅",IF(I9>=K9*0.8,"⚠️","❌")) -> ❌
A10: Records Pulled | B10: 120 | C10: 135 | D10: 128 | E10: 142 | F10: =SUM(B10:E10) -> 525 | H10: Qualified Leads | I10: 33 | J10: =IFERROR(I10/I9,0) -> 0.5 | K10: 40 | L10: =IF(I10>=K10,"✅",IF(I10>=K10*0.8,"⚠️","❌")) -> ⚠️
A11: Records Uploaded | B11: 115 | C11: 130 | D11: 122 | E11: 138 | F11: =SUM(B11:E11) -> 505 | H11: Appointments | I11: 18 | J11: =IFERROR(I11/I10,0) -> 0.54545455 | K11: 20 | L11: =IF(I11>=K11,"✅",IF(I11>=K11*0.8,"⚠️","❌")) -> ⚠️
A12: Records Enriched | B12: 110 | C12: 125 | D12: 118 | E12: 132 | F12: =SUM(B12:E12) -> 485 | H12: Offers Made | I12: 15 | J12: =IFERROR(I12/I11,0) -> 0.83333333 | K12: 15 | L12: =IF(I12>=K12,"✅",IF(I12>=K12*0.8,"⚠️","❌")) -> ✅
A13: Skip Trace Hit Rate | B13: 0.82 | C13: 0.85 | D13: 0.8 | E13: 0.84 | F13: =AVERAGE(B13:E13) -> 0.8275 | H13: Contracts | I13: 3 | J13: =IFERROR(I13/I12,0) -> 0.2 | K13: 2 | L13: =IF(I13>=K13,"✅",IF(I13>=K13*0.8,"⚠️","❌")) -> ✅
A14: Incomplete Resolved | B14: 8 | C14: 10 | D14: 9 | E14: 11 | F14: =SUM(B14:E14) -> 38 | H14: Closed Deals | I14: 1 | J14: =IFERROR(I14/I13,0) -> 0.33333333 | K14: 2 | L14: =IF(I14>=K14,"✅",IF(I14>=K14*0.8,"⚠️","❌")) -> ❌
A15: Deep Prospects Done | B15: 12 | C15: 15 | D15: 14 | E15: 16 | F15: =SUM(B15:E15) -> 57
H16: 📈 KEY RATIOS
A17: 📞 LEAD MANAGER KPIs | H17: Cost per Lead | I17: ='Monthly Data'!B15/I9 -> 0.045454545
A18: Metric | B18: Week 1 | C18: Week 2 | D18: Week 3 | E18: Week 4 | F18: MTD Total | H18: Cost per Contract | I18: ='Monthly Data'!B15/I13 -> 1
A19: New Leads Called | B19: 18 | C19: 22 | D19: 20 | E19: 25 | F19: =SUM(B19:E19) -> 85 | H19: Leads per Contract | I19: =IFERROR(I9/I13,0) -> 22
A20: Follow-ups Completed | B20: 45 | C20: 58 | D20: 52 | E20: 62 | F20: =SUM(B20:E20) -> 217 | H20: Close Rate | I20: =IFERROR(I14/I12,0) -> 0.066666667
A21: Tasks Completed | B21: 52 | C21: 65 | D21: 58 | E21: 70 | F21: =SUM(B21:E21) -> 245 | H21: ROI | I21: =IFERROR(I14*15000/'Monthly Data'!B15,0) -> 5000
A22: Overdue Tasks | B22: 3 | C22: 2 | D22: 4 | E22: 2 | F22: =SUM(B22:E22) -> 11
A23: Leads → Acquisitions | B23: 8 | C23: 10 | D23: 9 | E23: 12 | F23: =SUM(B23:E23) -> 39
A24: Ghosting Leads Recovered | B24: 2 | C24: 3 | D24: 2 | E24: 4 | F24: =SUM(B24:E24) -> 11 | H24: 📝 ACTION ITEMS / NOTES
A26: 🏠 ACQUISITIONS KPIs
A27: Metric | B27: Week 1 | C27: Week 2 | D27: Week 3 | E27: Week 4 | F27: MTD Total
A28: Appointments Set | B28: 5 | C28: 6 | D28: 4 | E28: 7 | F28: =SUM(B28:E28) -> 22
A29: Appointments Completed | B29: 4 | C29: 5 | D29: 4 | E29: 6 | F29: =SUM(B29:E29) -> 19
A30: Offers Made | B30: 3 | C30: 4 | D30: 3 | E30: 5 | F30: =SUM(B30:E30) -> 15
A31: Offers Accepted | B31: 2 | C31: 3 | D31: 2 | E31: 3 | F31: =SUM(B31:E31) -> 10
A32: Contracts Signed | B32: 1 | C32: 1 | D32: 0 | E32: 1 | F32: =SUM(B32:E32) -> 3
A33: Deals Closed | B33: 0 | C33: 1 | D33: 0 | E33: 0 | F33: =SUM(B33:E33) -> 1
A34: Revenue Generated | B34: 0 | C34: 30000 | D34: 0 | E34: 0 | F34: =SUM(B34:E34) -> 30000
